2022-10-15 14:07:26,204 ERROR: Exception on /index/ [GET] [in /Library/Frameworks/Python.framework/Versions/3.6/lib/python3.6/site-packages/flask/app.py:1892]
Traceback (most recent call last):
  File "/Library/Frameworks/Python.framework/Versions/3.6/lib/python3.6/site-packages/flask/app.py", line 2447, in wsgi_app
    response = self.full_dispatch_request()
  File "/Library/Frameworks/Python.framework/Versions/3.6/lib/python3.6/site-packages/flask/app.py", line 1952, in full_dispatch_request
    rv = self.handle_user_exception(e)
  File "/Library/Frameworks/Python.framework/Versions/3.6/lib/python3.6/site-packages/flask/app.py", line 1821, in handle_user_exception
    reraise(exc_type, exc_value, tb)
  File "/Library/Frameworks/Python.framework/Versions/3.6/lib/python3.6/site-packages/flask/_compat.py", line 39, in reraise
    raise value
  File "/Library/Frameworks/Python.framework/Versions/3.6/lib/python3.6/site-packages/flask/app.py", line 1950, in full_dispatch_request
    rv = self.dispatch_request()
  File "/Library/Frameworks/Python.framework/Versions/3.6/lib/python3.6/site-packages/flask/app.py", line 1936, in dispatch_request
    return self.view_functions[rule.endpoint](**req.view_args)
  File "/Library/Frameworks/Python.framework/Versions/3.6/lib/python3.6/site-packages/flask_login/utils.py", line 260, in decorated_view
    return current_app.login_manager.unauthorized()
  File "/Library/Frameworks/Python.framework/Versions/3.6/lib/python3.6/site-packages/flask_login/login_manager.py", line 175, in unauthorized
    redirect_url = make_login_url(login_view, next_url=request.url)
  File "/Library/Frameworks/Python.framework/Versions/3.6/lib/python3.6/site-packages/flask_login/utils.py", line 112, in login_url
    base = expand_login_view(login_view)
  File "/Library/Frameworks/Python.framework/Versions/3.6/lib/python3.6/site-packages/flask_login/utils.py", line 89, in expand_login_view
    return url_for(login_view)
  File "/Library/Frameworks/Python.framework/Versions/3.6/lib/python3.6/site-packages/flask/helpers.py", line 370, in url_for
    return appctx.app.handle_url_build_error(error, endpoint, values)
  File "/Library/Frameworks/Python.framework/Versions/3.6/lib/python3.6/site-packages/flask/app.py", line 2216, in handle_url_build_error
    reraise(exc_type, exc_value, tb)
  File "/Library/Frameworks/Python.framework/Versions/3.6/lib/python3.6/site-packages/flask/_compat.py", line 39, in reraise
    raise value
  File "/Library/Frameworks/Python.framework/Versions/3.6/lib/python3.6/site-packages/flask/helpers.py", line 358, in url_for
    endpoint, values, method=method, force_external=external
  File "/Library/Frameworks/Python.framework/Versions/3.6/lib/python3.6/site-packages/werkzeug/routing.py", line 2179, in build
    raise BuildError(endpoint, values, method, self)
werkzeug.routing.BuildError: Could not build url for endpoint 'login'. Did you mean 'auth.login' instead?
2022-10-15 14:11:04,270 INFO: Microblog startup [in /Users/sam/PycharmProjects/flask_lessons/app/__init__.py:69]
2022-10-15 14:11:06,311 ERROR: Exception on / [GET] [in /Library/Frameworks/Python.framework/Versions/3.6/lib/python3.6/site-packages/flask/app.py:1892]
Traceback (most recent call last):
  File "/Library/Frameworks/Python.framework/Versions/3.6/lib/python3.6/site-packages/flask/app.py", line 2447, in wsgi_app
    response = self.full_dispatch_request()
  File "/Library/Frameworks/Python.framework/Versions/3.6/lib/python3.6/site-packages/flask/app.py", line 1952, in full_dispatch_request
    rv = self.handle_user_exception(e)
  File "/Library/Frameworks/Python.framework/Versions/3.6/lib/python3.6/site-packages/flask/app.py", line 1821, in handle_user_exception
    reraise(exc_type, exc_value, tb)
  File "/Library/Frameworks/Python.framework/Versions/3.6/lib/python3.6/site-packages/flask/_compat.py", line 39, in reraise
    raise value
  File "/Library/Frameworks/Python.framework/Versions/3.6/lib/python3.6/site-packages/flask/app.py", line 1950, in full_dispatch_request
    rv = self.dispatch_request()
  File "/Library/Frameworks/Python.framework/Versions/3.6/lib/python3.6/site-packages/flask/app.py", line 1936, in dispatch_request
    return self.view_functions[rule.endpoint](**req.view_args)
  File "/Library/Frameworks/Python.framework/Versions/3.6/lib/python3.6/site-packages/flask_login/utils.py", line 260, in decorated_view
    return current_app.login_manager.unauthorized()
  File "/Library/Frameworks/Python.framework/Versions/3.6/lib/python3.6/site-packages/flask_login/login_manager.py", line 175, in unauthorized
    redirect_url = make_login_url(login_view, next_url=request.url)
  File "/Library/Frameworks/Python.framework/Versions/3.6/lib/python3.6/site-packages/flask_login/utils.py", line 112, in login_url
    base = expand_login_view(login_view)
  File "/Library/Frameworks/Python.framework/Versions/3.6/lib/python3.6/site-packages/flask_login/utils.py", line 89, in expand_login_view
    return url_for(login_view)
  File "/Library/Frameworks/Python.framework/Versions/3.6/lib/python3.6/site-packages/flask/helpers.py", line 370, in url_for
    return appctx.app.handle_url_build_error(error, endpoint, values)
  File "/Library/Frameworks/Python.framework/Versions/3.6/lib/python3.6/site-packages/flask/app.py", line 2216, in handle_url_build_error
    reraise(exc_type, exc_value, tb)
  File "/Library/Frameworks/Python.framework/Versions/3.6/lib/python3.6/site-packages/flask/_compat.py", line 39, in reraise
    raise value
  File "/Library/Frameworks/Python.framework/Versions/3.6/lib/python3.6/site-packages/flask/helpers.py", line 358, in url_for
    endpoint, values, method=method, force_external=external
  File "/Library/Frameworks/Python.framework/Versions/3.6/lib/python3.6/site-packages/werkzeug/routing.py", line 2179, in build
    raise BuildError(endpoint, values, method, self)
werkzeug.routing.BuildError: Could not build url for endpoint 'login'. Did you mean 'auth.login' instead?
2022-10-15 14:18:54,162 INFO: Microblog startup [in /Users/sam/PycharmProjects/flask_lessons/app/__init__.py:69]
2022-10-15 14:19:12,392 ERROR: Exception on /auth/reset_password_request/ [POST] [in /Library/Frameworks/Python.framework/Versions/3.6/lib/python3.6/site-packages/flask/app.py:1892]
Traceback (most recent call last):
  File "/Library/Frameworks/Python.framework/Versions/3.6/lib/python3.6/site-packages/flask/app.py", line 2447, in wsgi_app
    response = self.full_dispatch_request()
  File "/Library/Frameworks/Python.framework/Versions/3.6/lib/python3.6/site-packages/flask/app.py", line 1952, in full_dispatch_request
    rv = self.handle_user_exception(e)
  File "/Library/Frameworks/Python.framework/Versions/3.6/lib/python3.6/site-packages/flask/app.py", line 1821, in handle_user_exception
    reraise(exc_type, exc_value, tb)
  File "/Library/Frameworks/Python.framework/Versions/3.6/lib/python3.6/site-packages/flask/_compat.py", line 39, in reraise
    raise value
  File "/Library/Frameworks/Python.framework/Versions/3.6/lib/python3.6/site-packages/flask/app.py", line 1950, in full_dispatch_request
    rv = self.dispatch_request()
  File "/Library/Frameworks/Python.framework/Versions/3.6/lib/python3.6/site-packages/flask/app.py", line 1936, in dispatch_request
    return self.view_functions[rule.endpoint](**req.view_args)
  File "/Users/sam/PycharmProjects/flask_lessons/app/auth/routes.py", line 75, in reset_password_request
    send_password_reset_email(user)
  File "/Users/sam/PycharmProjects/flask_lessons/app/auth/email.py", line 15, in send_password_reset_email
    sender=config.Config.MAIL_USERNAME,
AttributeError: type object 'Config' has no attribute 'MAIL_USERNAME'
2022-10-15 14:20:20,647 INFO: Microblog startup [in /Users/sam/PycharmProjects/flask_lessons/app/__init__.py:69]
2022-10-15 14:21:37,629 INFO: Microblog startup [in /Users/sam/PycharmProjects/flask_lessons/app/__init__.py:69]
2022-10-15 14:42:12,679 INFO: Microblog startup [in /Users/sam/PycharmProjects/flask_lessons/app/__init__.py:69]
2022-10-15 14:46:45,682 INFO: Microblog startup [in /Users/sam/PycharmProjects/flask_lessons/app/__init__.py:69]
2022-10-15 14:49:38,554 INFO: Microblog startup [in /Users/sam/PycharmProjects/flask_lessons/app/__init__.py:69]
